<mujoco model="DIP-Flex_closed_chain">
  <option timestep="1e-4"/>
  <option gravity="0 0 -9.81"/>
  <option integrator="implicitfast"/>

  <compiler meshdir="assets" eulerseq="zyx" autolimits="true"/>

  <default>
    <joint damping="0.2" armature="0.01" frictionloss="0.01"/>
    <geom condim="4" contype="1" conaffinity="2" friction="0.9 0.2 0.2" solref="0.001 "/>
    <motor ctrllimited="true"/>
    <position ctrllimited="true" dampratio="1" kp="10000"/>
    <equality solref="0.00001 1"/>
    <default class="visualgeom">
      <geom material="visualgeom" condim="1" contype="0" conaffinity="0"/>
    </default>
  </default>

  <asset>
    <texture type="skybox" builtin="gradient" rgb1="1 1 1" rgb2="0.5 0.5 0.5" width="265" height="256"/>
    <mesh name="base_link" file="base_link.STL" />
    <mesh name="Link_pinkie_abduction" file="Link_pinkie_abduction.STL" />
    <mesh name="Link_pinkie_PPflexion" file="Link_pinkie_PPflexion.STL" />
    <mesh name="Link_pinkie_DPflexion" file="Link_pinkie_DPflexion.STL" />
    <mesh name="Link_pinkie_dynamixel_crank" file="Link_pinkie_dynamixel_crank.STL" />
    <mesh name="Link_pinkie_crank_pusher" file="Link_pinkie_crank_pusher.STL" />
    <mesh name="Link_index_abduction" file="Link_index_abduction.STL" />
    <mesh name="Link_index_PPflexion" file="Link_index_PPflexion.STL" />
    <mesh name="Link_index_DPflexion" file="Link_index_DPflexion.STL" />
    <mesh name="Link_index_dynamixel_crank" file="Link_index_dynamixel_crank.STL" />
    <mesh name="Link_index_crank_pusher" file="Link_index_crank_pusher.STL" />
    <mesh name="Link_thumb_rotation" file="Link_thumb_rotation.STL" />
    <mesh name="Link_thumb_abduction" file="Link_thumb_abduction.STL" />
    <mesh name="Link_thumb_PPflexion" file="Link_thumb_PPflexion.STL" />
    <mesh name="Link_thumb_DPflexion" file="Link_thumb_DPflexion.STL" />
    <mesh name="Link_thumb_dynamixel_crank" file="Link_thumb_dynamixel_crank.STL" />
    <mesh name="Link_thumb_crank_pusher" file="Link_thumb_crank_pusher.STL" />
    <texture name="texplane" type="2d" builtin="checker" rgb1=".0 .0 .0" rgb2=".8 .8 .8" width="100" height="100" />
    <material name="matplane" reflectance="0." texture="texplane" texrepeat="1 1" texuniform="true" />
    <material name="visualgeom" rgba="0.5 0.9 0.2 1" />
  </asset>

  <worldbody>
    <light directional="true" diffuse="0.4 0.4 0.4" specular="0.1 0.1 0.1" pos="0 0 5.0" dir="0 0 -1" castshadow="false" />
    <light directional="true" diffuse="0.6 0.6 0.6" specular="0.2 0.2 0.2" pos="0 0 4" dir="0 0 -1" />



    <camera name="fixed" pos="0 -3.0 0.6166426767051374" xyaxes="1 0 0 0 0 1" />
    <camera name="track" mode="trackcom" pos="0 -3.0 0.6166426767051374" xyaxes="1 0 0 0 0 1" />
    <body name="root" pos="0 0 0.11664267670513738" quat="1 0 0 0">
      <geom type="mesh" rgba="0.79216 0.81961 0.93333 1" mesh="base_link" conaffinity="0" density="0" group="1" class="visualgeom" />
      <geom type="mesh" rgba="0.79216 0.81961 0.93333 1" mesh="base_link" />
      <body name="Link_pinkie_abduction" pos="-0.022 0 0" quat="0.499998 0.5 -0.5 0.500002">
        <inertial pos="0.0087427 0.0066478 -0.0042803" quat="0.908826 0.311338 -0.27734 -0.0136686" mass="0.014579" diaginertia="5.54964e-06 4.48262e-06 2.72704e-06" />
        <joint name="Joint_pinkie_abduction" pos="0 0 0" axis="0 0 1" range="-360 360"/>
        <geom type="mesh" rgba="1 1 1 1" mesh="Link_pinkie_abduction" conaffinity="0" density="0" group="1" class="visualgeom" />
        <geom type="mesh" rgba="1 1 1 1" mesh="Link_pinkie_abduction" />
        <body name="Link_pinkie_PPflexion" pos="0 0 0.0135" quat="0.705383 -0.705386 -0.0493265 -0.0493267">
          <inertial pos="0.023519 -0.0040969 -9.2833e-06" quat="0.496939 0.49772 0.503047 0.502265" mass="0.037156" diaginertia="1.16828e-05 8.07601e-06 4.62059e-06" />
          <joint name="Joint_pinkie_PPflexion" pos="0 0 0" axis="0 0 -1" range="0 90"/>
          <geom type="mesh" rgba="1 1 1 1" mesh="Link_pinkie_PPflexion" conaffinity="0" density="0" group="1" class="visualgeom" />
          <geom type="mesh" rgba="1 1 1 1" mesh="Link_pinkie_PPflexion" />
          <body name="Link_pinkie_DPflexion" pos="0.05 0 0" quat="0.984984 0 0 -0.172646">
            <inertial pos="0.008247 0.011323 -0.00021313" quat="-0.245607 0.662281 0.246851 0.66342" mass="0.048224" diaginertia="5.79821e-06 4.61748e-06 4.23322e-06" />
            <joint name="Joint_pinkie_DPflexion" pos="0 0 0" axis="0 0 -1" stiffness="0.1" springref="-74" range="0 90"/>
            <geom type="mesh" rgba="0.79216 0.81961 0.93333 1" mesh="Link_pinkie_DPflexion" conaffinity="0" density="0" group="1" class="visualgeom" />
            <site name="pinkie_DP_S1" size="0.001" pos="0 0.025 0" />
            <geom type="mesh" rgba="0.79216 0.81961 0.93333 1" mesh="Link_pinkie_DPflexion" />
          </body>
        </body>
        <body name="Link_pinkie_dynamixel_crank" pos="0.034 0 -0.0065" quat="-0.390231 0.390225 0.589682 0.589677">
          <inertial pos="-0.0292247 -0.000345549 -0.00845468" quat="0.417549 0.571984 0.530843 0.465503" mass="0.00941503" diaginertia="4.29661e-06 4.03026e-06 6.59128e-07" />
          <joint name="Joint_pinkie_dynamixel_crank" pos="0 0 0" axis="0 0 -1" range="0 90"/>
          <geom type="mesh" rgba="1 1 1 1" mesh="Link_pinkie_dynamixel_crank" conaffinity="0" density="0" group="1" class="visualgeom" />
          <geom type="mesh" rgba="1 1 1 1" mesh="Link_pinkie_dynamixel_crank" />
          <body name="Link_pinkie_crank_pusher" pos="-0.062 0 0" quat="0.974848 0 0 0.222872">
            <inertial pos="0.0275328 0 -1.27018e-05" quat="0.49959 0.50041 0.50041 0.49959" mass="0.0133255" diaginertia="4.49962e-06 4.09926e-06 5.43377e-07" />
            <joint name="Joint_pinkie_crank_pusher" pos="0 0 0" axis="0 0 -1" range="0 90"/>
            <geom type="mesh" rgba="1 1 1 1" mesh="Link_pinkie_crank_pusher" conaffinity="0" density="0" group="1" class="visualgeom" />
            <site name="pinkie_cra_S2" size="0.001" pos="0.062 0 0" />
            <geom type="mesh" rgba="1 1 1 1" mesh="Link_pinkie_crank_pusher" />
          </body>
        </body>
      </body>
      <body name="Link_index_abduction" pos="0.022 0 0" quat="0.499998 0.5 -0.5 0.500002">
        <inertial pos="0.00874274 -0.00664781 -0.00428031" quat="0.908825 -0.31134 -0.277341 0.0136712" mass="0.014579" diaginertia="5.54959e-06 4.4826e-06 2.72703e-06" />
        <joint name="Joint_index_abduction" pos="0 0 0" axis="0 0 -1" range="0 90"/>
        <geom type="mesh" rgba="1 1 1 1" mesh="Link_index_abduction" conaffinity="0" density="0" group="1" class="visualgeom" />
        <geom type="mesh" rgba="1 1 1 1" mesh="Link_index_abduction" />
        <body name="Link_index_PPflexion" pos="0 0 0.0135" quat="0.705383 -0.705386 -0.0493265 -0.0493267">
          <inertial pos="0.0235185 -0.00409688 -0.000291063" quat="0.497746 0.496912 0.502224 0.503088" mass="0.0371563" diaginertia="1.16823e-05 8.07597e-06 4.62054e-06" />
          <joint name="Joint_index_PPflexion" pos="0 0 0" axis="0 0 -1" range="0 90"/>
          <geom type="mesh" rgba="1 1 1 1" mesh="Link_index_PPflexion" conaffinity="0" density="0" group="1" class="visualgeom" />
          <geom type="mesh" rgba="1 1 1 1" mesh="Link_index_PPflexion" />
          <body name="Link_index_DPflexion" pos="0.05 0 0" quat="0.984984 0 0 -0.172646">
            <inertial pos="0.0199696 0.00918915 -0.000300157" quat="0.0325537 0.706363 -0.0323876 0.706358" mass="0.0184277" diaginertia="3.35052e-06 3.19075e-06 1.41972e-06" />
            <joint name="Joint_index_DPflexion" pos="0 0 0" axis="0 0 -1" stiffness="0.1" springref="-74" range="0 90"/>
            <geom type="mesh" rgba="1 1 1 1" mesh="Link_index_DPflexion" conaffinity="0" density="0" group="1" class="visualgeom" />
            <site name="index_DP_S1" size="0.001" pos="0 0.025 0" />
            <geom type="mesh" rgba="1 1 1 1" mesh="Link_index_DPflexion" />
          </body>
        </body>
        <body name="Link_index_dynamixel_crank" pos="0.034 0 -0.0065" quat="0.390227 -0.39023 -0.589679 -0.58968">
          <inertial pos="-0.0292247 -0.000345549 0.00815468" quat="0.571984 0.417549 0.465503 0.530843" mass="0.00941503" diaginertia="4.29661e-06 4.03026e-06 6.59128e-07" />
          <joint name="Joint_index_dynamixel_crank" pos="0 0 0" axis="0 0 -1" range="0 90"/>
          <geom type="mesh" rgba="1 1 1 1" mesh="Link_index_dynamixel_crank" conaffinity="0" density="0" group="1" class="visualgeom" />
          <geom type="mesh" rgba="1 1 1 1" mesh="Link_index_dynamixel_crank" />
          <body name="Link_index_crank_pusher" pos="-0.062 0 0" quat="0.974848 0 0 0.222872">
            <inertial pos="0.0275328 0 -0.000287298" quat="0.50041 0.49959 0.49959 0.50041" mass="0.0133255" diaginertia="4.49962e-06 4.09926e-06 5.43377e-07" />
            <joint name="Joint_index_crank_pusher" pos="0 0 0" axis="0 0 1" range="0 90"/>
            <geom type="mesh" rgba="1 1 1 1" mesh="Link_index_crank_pusher" conaffinity="0" density="0" group="1" class="visualgeom" />
            <site name="index_cra_S2" size="0.001" pos="0.062 0 0" />
            <geom type="mesh" rgba="1 1 1 1" mesh="Link_index_crank_pusher" />
          </body>
        </body>
      </body>
      <body name="Link_thumb_rotation" pos="0.0392 -0.031 -0.062" quat="0.707105 0.707108 0 0">
        <inertial pos="-0.0113436 0 0.00225278" quat="0.508482 0.508482 -0.491372 0.491372" mass="0.00539304" diaginertia="1.19125e-06 7.86827e-07 4.45909e-07" />
        <joint name="Joint_thumb_rotation" pos="0 0 0" axis="0 0 -1" range="-90 90"/>
        <geom type="mesh" rgba="1 1 1 1" mesh="Link_thumb_rotation" conaffinity="0" density="0" group="1" class="visualgeom" />
        <geom type="mesh" rgba="1 1 1 1" mesh="Link_thumb_rotation" />
        <body name="Link_thumb_abduction" pos="0 0.021 0.02" quat="0.707105 -0.707108 0 0">
          <inertial pos="0.00874274 -0.00664781 -0.00428031" quat="0.908825 -0.31134 -0.277341 0.0136712" mass="0.014579" diaginertia="5.54959e-06 4.4826e-06 2.72703e-06" />
          <joint name="Joint_thumb_abduction" pos="0 0 0" axis="0 0 -1" range="0 90"/>
          <geom type="mesh" rgba="1 1 1 1" mesh="Link_thumb_abduction" conaffinity="0" density="0" group="1" class="visualgeom" />
          <geom type="mesh" rgba="1 1 1 1" mesh="Link_thumb_abduction" />
          <body name="Link_thumb_PPflexion" pos="0 0 0.0135" quat="0.705383 -0.705386 -0.0493265 -0.0493267">
            <inertial pos="0.0235185 -0.00409688 -0.000291063" quat="0.497746 0.496912 0.502224 0.503088" mass="0.0371563" diaginertia="1.16823e-05 8.07597e-06 4.62054e-06" />
            <joint name="Joint_thumb_PPflexion" pos="0 0 0" axis="0 0 -1" range="0 90"/>
            <geom type="mesh" rgba="1 1 1 1" mesh="Link_thumb_PPflexion" conaffinity="0" density="0" group="1" class="visualgeom" />
            <geom type="mesh" rgba="1 1 1 1" mesh="Link_thumb_PPflexion" />
            <body name="Link_thumb_DPflexion" pos="0.05 0 0" quat="0.984984 0 0 -0.172646">
              <inertial pos="0.0199696 0.00918915 -0.000300157" quat="0.0325537 0.706363 -0.0323876 0.706358" mass="0.0184277" diaginertia="3.35052e-06 3.19075e-06 1.41972e-06" />
              <joint name="Joint_thumb_DPflexion" pos="0 0 0" axis="0 0 -1" stiffness="0.1" springref="-74" range="0 90"/>
              <geom type="mesh" rgba="1 1 1 1" mesh="Link_thumb_DPflexion" conaffinity="0" density="0" group="1" class="visualgeom" />
              <site name="thumb_DP_S1" size="0.001" pos="0 0.025 0" />
              <geom type="mesh" rgba="1 1 1 1" mesh="Link_thumb_DPflexion" />
            </body>
          </body>
          <body name="Link_thumb_dynamixel_crank" pos="0.034 0 -0.0065" quat="-0.390231 0.390225 0.589682 0.589677">
            <inertial pos="-0.0292247 -0.000345549 0.00815468" quat="0.571984 0.417549 0.465503 0.530843" mass="0.00941503" diaginertia="4.29661e-06 4.03026e-06 6.59128e-07" />
            <joint name="Joint_thumb_dynamixel_crank" pos="0 0 0" axis="0 0 -1" range="0 90"/>
            <geom type="mesh" rgba="1 1 1 1" mesh="Link_thumb_dynamixel_crank" conaffinity="0" density="0" group="1" class="visualgeom" />
            <geom type="mesh" rgba="1 1 1 1" mesh="Link_thumb_dynamixel_crank" />
            <body name="Link_thumb_crank_pusher" pos="-0.062 0 0" quat="0.974848 0 0 0.222872">
              <inertial pos="0.0275328 0 -0.000287298" quat="0.50041 0.49959 0.49959 0.50041" mass="0.0133255" diaginertia="4.49962e-06 4.09926e-06 5.43377e-07" />
              <joint name="Joint_thumb_crank_pusher" pos="0 0 0" axis="0 0 1" range="0 90"/>
              <geom type="mesh" rgba="1 1 1 1" mesh="Link_thumb_crank_pusher" conaffinity="0" density="0" group="1" class="visualgeom" />
              <site name="thumb_cra_S2" size="0.001" pos="0.062 0 0" />
              <geom type="mesh" rgba="1 1 1 1" mesh="Link_thumb_crank_pusher" />
            </body>
          </body>
        </body>
      </body>
    </body>
  </worldbody>


  <actuator>
    <position name="Joint_pinkie_abduction_p" joint="Joint_pinkie_abduction" ctrlrange="0 90" timeconst="1"/>
    <position name="Joint_index_abduction_p" joint="Joint_index_abduction" ctrlrange="0 90" timeconst="1"/>
    <position name="Joint_thumb_abduction_p" joint="Joint_thumb_abduction" ctrlrange="0 90" timeconst="1"/>

    <position name="Joint_pinkie_PPflexion_p" joint="Joint_pinkie_PPflexion" ctrlrange="0 90" timeconst="1"/>
    <position name="Joint_index_PPflexion_p" joint="Joint_index_PPflexion" ctrlrange="0 90" timeconst="1"/>
    <position name="Joint_thumb_PPflexion_p" joint="Joint_thumb_PPflexion" ctrlrange="0 90" timeconst="1"/>

    <position name="Joint_pinkie_DPflexion_p" joint="Joint_pinkie_DPflexion" ctrlrange="0 90" timeconst="1"/>
    <position name="Joint_index_DPflexion_p" joint="Joint_index_DPflexion" ctrlrange="0 90" timeconst="1"/>
    <position name="Joint_thumb_DPflexion_p" joint="Joint_thumb_DPflexion" ctrlrange="0 90" timeconst="1"/>

    <position name="Joint_thumb_rotation_p" joint="Joint_thumb_rotation" ctrlrange="-90 90" timeconst="1"/>

    <!--Closed chain joints-->
    <position name="Joint_pinkie_dynamixel_crank_p" joint="Joint_pinkie_dynamixel_crank" ctrlrange="0 90" timeconst="1"/>
    <position name="Joint_index_dynamixel_crank_p" joint="Joint_index_dynamixel_crank" ctrlrange="0 90" timeconst="1"/>
    <position name="Joint_thumb_dynamixel_crank_p" joint="Joint_thumb_dynamixel_crank" ctrlrange="0 90" timeconst="1"/>
  </actuator>


  <sensor>

  </sensor>

  <equality>
    <connect name="Connect_pinkie" site1="pinkie_DP_S1" site2="pinkie_cra_S2"/>
    <connect name="Connect_index" site1="index_DP_S1" site2="index_cra_S2"/>
    <connect name="Connect_thumb" site1="thumb_DP_S1" site2="thumb_cra_S2"/>
  </equality>

</mujoco>