<?xml version='1.0' encoding='UTF-8'?>
<mujoco model="DP-Flex_closed_kinematics">
  <option timestep="1e-4"/>
  <option gravity="0 0 0"/>
  <option integrator="implicitfast"/>
  <compiler meshdir="assets" eulerseq="zyx" autolimits="true"/>
  <default>
    <joint damping="0.2" armature="0.01" frictionloss="0.01"/>
    <geom condim="4" contype="1" conaffinity="15" friction="0.9 0.2 0.2" solref="0.001 2"/>
    <motor ctrllimited="true"/>
    <position ctrllimited="true"/>
    <equality solref="0.001 2"/>
    <default class="visualgeom">
      <geom material="visualgeom" condim="1" contype="0" conaffinity="0"/>
    </default>
  </default>
  <asset>
    <texture type="skybox" builtin="gradient" rgb1="1 1 1" rgb2="0.5 0.5 0.5" width="265" height="256"/>
    <mesh name="base_link" file="base_link.STL"/>
    <mesh name="Link_left_abduction" file="Link_left_abduction.STL"/>
    <mesh name="Link_left_flexion" file="Link_left_flexion.STL"/>
    <mesh name="Link_left_finray_proxy" file="Link_left_finray_proxy.STL"/>
    <mesh name="Link_right_abduction" file="Link_right_abduction.STL"/>
    <mesh name="Link_right_flexion" file="Link_right_flexion.STL"/>
    <mesh name="Link_right_finray_proxy" file="Link_right_finray_proxy.STL"/>
    <mesh name="Link_thumb_rotation" file="Link_thumb_rotation.STL"/>
    <mesh name="Link_thumb_abduction" file="Link_thumb_abduction.STL"/>
    <mesh name="Link_thumb_flexion" file="Link_thumb_flexion.STL"/>
    <mesh name="Link_thumb_finray_proxy" file="Link_thumb_finray_proxy.STL"/>
    <texture name="texplane" type="2d" builtin="checker" rgb1=".0 .0 .0" rgb2=".8 .8 .8" width="100" height="100"/>
    <material name="matplane" reflectance="0." texture="texplane" texrepeat="1 1" texuniform="true"/>
    <material name="visualgeom" rgba="0.5 0.9 0.2 1"/>
    <material name="prim_mat" rgba="0.792157 0.819608 0.933333 1"/>
  </asset>
  <worldbody>
    <light directional="true" diffuse="0.4 0.4 0.4" specular="0.1 0.1 0.1" pos="0 0 5.0" dir="0 0 -1" castshadow="false"/>
    <light directional="true" diffuse="0.6 0.6 0.6" specular="0.2 0.2 0.2" pos="0 0 4" dir="0 0 -1"/>
    <camera name="fixed" pos="0 -3.0 0.5218365472531615" xyaxes="1 0 0 0 0 1"/>
    <camera name="track" mode="trackcom" pos="0 -3.0 0.5218365472531615" xyaxes="1 0 0 0 0 1"/>
    <body name="root" pos="0 0 0" euler="0 0 0">
      <geom type="box" size="0.046000 0.060781 0.047407" pos="-0.006000 0.018441 0.047407" quat="1.000000 0.000000 0.000000 0.000000" material="prim_mat" contype="1" conaffinity="15"/>
      <body name="Link_left_abduction" pos="-0.033 0.044564 0.07714" quat="0.984807 0.17365 0 0">
        <inertial pos="-0.009332 0.029641 -0.016496" quat="-0.6235992262412688 -0.446378711309853 0.6417685277499686 -0.0017910640088146476" mass="0.051148" diaginertia="1.203600e-08 2.013255e-08 2.100335e-08"/>
        <joint name="Joint_left_abduction" pos="0 0 0" axis="0 0 1" range="0 90"/>
        <geom type="box" size="0.023644 0.033491 0.031249" pos="-0.006656 0.016509 -0.013751" quat="1.000000 0.000000 0.000000 0.000000" material="prim_mat" contype="1" conaffinity="15"/>
        <body name="Link_left_flexion" pos="0.0145 0 0.0135" quat="0.707105 0 0.707108 0">
          <inertial pos="-0.007468 0.022758 -0.014491" quat="-0.4630821096163084 -0.46401458426074643 -0.5337396061169267 0.5341979578852619" mass="0.028728" diaginertia="3.814508e-09 6.422191e-09 9.106331e-09"/>
          <joint name="Joint_left_flexion" pos="0 0 0" axis="0 0 1" range="0 90"/>
          <geom type="ellipsoid" size="0.009000 0.021429 0.028970" pos="-0.008426 0.024031 -0.014500" quat="0.705384 -0.705384 -0.049325 0.049325" material="prim_mat" contype="1" conaffinity="15"/>
          <body name="Link_left_finray_proxy" pos="-0.0069587 0.049513 -0.0045">
            <inertial pos="-0.001736 0.022618 -0.009800" quat="-1.561525959141133e-05 0.4229383694155905 0.9061584482632186 4.5535051240073894e-05" mass="0.014125" diaginertia="1.206813e-09 5.907188e-09 6.144261e-09"/>
            <joint name="Joint_left_finray_proxy" pos="0 0 0" axis="0 0 1" range="0 70" stiffness="0" springref="-74"/>
            <geom type="capsule" size="0.015712 0.018701" pos="-0.006698 0.026266 -0.010086" quat="0.263423 -0.688993 0.300062 0.604864" material="prim_mat" contype="1" conaffinity="15"/>
          </body>
        </body>
      </body>
      <body name="Link_right_abduction" pos="0.011 0.044564 0.07714" quat="0.984807 0.17365 0 0">
        <inertial pos="0.009565 0.029612 -0.016480" quat="0.638892318147617 6.482824890542196e-06 -0.6238099429304945 0.45019746875231365" mass="0.051160" diaginertia="1.203057e-08 2.012683e-08 2.105357e-08"/>
        <joint name="Joint_right_abduction" pos="0 0 0" axis="0 0 -1" range="0 90"/>
        <geom type="box" size="0.023644 0.033491 0.031249" pos="0.006656 0.016509 -0.013751" quat="1.000000 0.000000 0.000000 0.000000" material="prim_mat" contype="1" conaffinity="15"/>
        <body name="Link_right_flexion" pos="-0.0145 0 0.0135" quat="0.707105 0 0.707108 0">
          <inertial pos="-0.007468 0.022759 0.014792" quat="0.4640194547497596 0.463081525208765 0.5341894892865027 -0.5337443546866658" mass="0.028729" diaginertia="3.814533e-09 6.422295e-09 9.106414e-09"/>
          <joint name="Joint_right_flexion" pos="0 0 0" axis="0 0 1" range="0 90"/>
          <geom type="ellipsoid" size="0.009000 0.021429 0.028970" pos="-0.008426 0.024031 0.014800" quat="0.705384 0.705384 0.049325 0.049325" material="prim_mat" contype="1" conaffinity="15"/>
          <body name="Link_right_finray_proxy" pos="-0.0069587 0.049513 0.0048">
            <inertial pos="-0.001736 0.022618 0.010000" quat="-1.0457691563451743e-05 0.4229366756220633 0.9061592392617048 3.748389642000896e-05" mass="0.014125" diaginertia="1.206821e-09 5.907223e-09 6.144301e-09"/>
            <joint name="Joint_right_finray_proxy" pos="0 0 0" axis="0 0 1" range="0 70" stiffness="0" springref="-74"/>
            <geom type="capsule" size="0.015000 0.019147" pos="-0.006769 0.026948 0.009999" quat="0.645896 0.287782 0.645896 -0.287782" material="prim_mat" contype="1" conaffinity="15"/>
          </body>
        </body>
      </body>
      <body name="Link_thumb_rotation" pos="0.0282 -0.024299 0.085066" quat="0.984807 0.17365 0 0">
        <inertial pos="-0.012462 0.000702 0.018566" quat="0.9992673782272922 -0.020782076550420105 -0.009188943177094741 -0.030795704705274225" mass="0.047107" diaginertia="8.442760e-09 1.196492e-08 1.327989e-08"/>
        <joint name="Joint_thumb_rotation" pos="0 0 0" axis="0 0 1"/>
        <geom type="box" size="0.025000 0.020273 0.018000" pos="-0.013500 0.001273 0.018000" quat="1.000000 0.000000 0.000000 0.000000" material="prim_mat" contype="1" conaffinity="15"/>
        <body name="Link_thumb_abduction" pos="0 0.021 0.02" quat="0.707105 -0.707108 0 0">
          <inertial pos="-0.009565 -0.029612 -0.016480" quat="6.482824891237288e-06 0.6388923181476168 -0.45019746875231337 0.6238099429304947" mass="0.051160" diaginertia="1.203057e-08 2.012683e-08 2.105357e-08"/>
          <joint name="Joint_thumb_abduction" pos="0 0 0" axis="0 0 1" range="0 90"/>
          <geom type="box" size="0.023644 0.033491 0.031249" pos="-0.006656 -0.016509 -0.013751" quat="1.000000 0.000000 0.000000 0.000000" material="prim_mat" contype="1" conaffinity="15"/>
          <body name="Link_thumb_flexion" pos="0.0145 0 0.0135" quat="0.499998 0.5 0.500002 0.5">
            <inertial pos="-0.022759 0.007468 -0.014792" quat="0.7055255556750184 0.7051770970303916 -0.05028092359573776 0.04930294956293985" mass="0.028729" diaginertia="3.814533e-09 6.422295e-09 9.106414e-09"/>
            <joint name="Joint_thumb_flexion" pos="0 0 0" axis="0 0 -1" range="0 90"/>
            <geom type="ellipsoid" size="0.009000 0.021429 0.028970" pos="-0.024031 0.008426 -0.014800" quat="0.533660 0.533660 0.463904 0.463904" material="prim_mat" contype="1" conaffinity="15"/>
            <body name="Link_thumb_finray_proxy" pos="-0.049513 0.0069587 -0.0048">
              <inertial pos="-0.022618 0.001736 -0.010000" quat="0.9398127342616509 3.3899821964835085e-05 -1.9110412724092084e-05 0.34168995157193854" mass="0.014125" diaginertia="1.206821e-09 5.907223e-09 6.144301e-09"/>
              <joint name="Joint_thumb_finray_proxy" pos="0 0 0" axis="0 0 -1" range="0 70" stiffness="0" springref="-74"/>
              <geom type="capsule" size="0.015712 0.018701" pos="-0.026266 0.006698 -0.009714" quat="0.241435 0.699367 -0.275016 0.613972" material="prim_mat" contype="1" conaffinity="15"/>
            </body>
          </body>
        </body>
      </body>
      <inertial pos="-0.005984 0.009720 0.047763" quat="0.8871513595811813 -0.05802045648788138 0.16592504209001802 0.4266907219868098" mass="0.389760" diaginertia="3.793148e-07 4.525607e-07 4.732907e-07"/>
    </body>
  </worldbody>
  <actuator>
    <position name="Joint_left_abduction_p" joint="Joint_left_abduction" ctrlrange="0 90" timeconst="1"/>
    <position name="Joint_right_abduction_p" joint="Joint_right_abduction" ctrlrange="0 90" timeconst="1"/>
    <position name="Joint_thumb_abduction_p" joint="Joint_thumb_abduction" ctrlrange="0 90" timeconst="1"/>
    <position name="Joint_left_flexion_p" joint="Joint_left_flexion" ctrlrange="0 90" timeconst="1"/>
    <position name="Joint_right_flexion_p" joint="Joint_right_flexion" ctrlrange="0 90" timeconst="1"/>
    <position name="Joint_thumb_flexion_p" joint="Joint_thumb_flexion" ctrlrange="0 90" timeconst="1"/>
    <position name="Joint_left_finray_proxy_p" joint="Joint_left_finray_proxy" ctrlrange="0 70" timeconst="1"/>
    <position name="Joint_right_finray_proxy_p" joint="Joint_right_finray_proxy" ctrlrange="0 70" timeconst="1"/>
    <position name="Joint_thumb_finray_proxy_p" joint="Joint_thumb_finray_proxy" ctrlrange="0 70" timeconst="1"/>
    <position name="Joint_thumb_rotation_p" joint="Joint_thumb_rotation" ctrlrange="-90 90" timeconst="1"/>
  </actuator>
</mujoco>
