<mujoco model="hand_asembly_ver2_URDF_4">
  <compiler angle="radian" meshdir="meshes"/>
  <!-- <option apirate="200" iterations="20"/> -->

  <default>
    <joint damping=".01"/>
    <position kp="1"/>
    <geom density="500" contype="0" conaffinity="0" group="2"/> 
  </default>

  <asset>
    <mesh name="base_link" file="base_link.STL"/>
    <mesh name="proximal_thumb" file="proximal_thumb.STL"/>
    <mesh name="mideal_thumb" file="mideal_thumb.STL"/>
    <mesh name="distal_thumb" file="distal_thumb.STL"/>
    <mesh name="proximal_finger_first" file="proximal_finger_first.STL"/>
    <mesh name="mideal_finger first" file="mideal_finger first.STL"/>
    <mesh name="distal_finger first" file="distal_finger first.STL"/>
    <mesh name="proximal_finger_second" file="proximal_finger_second.STL"/>
    <mesh name="mideal_finger_second" file="mideal_finger_second.STL"/>
    <mesh name="distal_finger_second" file="distal_finger_second.STL"/>
  </asset>

  <worldbody>
    <geom type="mesh" rgba="0.792157 0.819608 0.933333 1" mesh="base_link"/>
    <geom pos="-0.0316 0.05702 0.025" quat="0.707105 0 -0.707108 0" type="mesh" rgba="0.792157 0.819608 0.933333 1" mesh="proximal_finger_first"/>
    <geom pos="0.0182 0.05702 0.025" quat="0.707107 0 -0.707107 0" type="mesh" rgba="0.792157 0.819608 0.933333 1" mesh="proximal_finger_second"/>

    <body name="proximal_thumb" pos="-0.05532 -0.00754 0.0075" quat="0.477798 0 0 0.87847">
      <inertial pos="0.0284057 -0.0131974 0.0551741" quat="0.710418 0.565303 -0.418745 -0.0197706" mass="1.85313" diaginertia="0.00127875 0.00126164 0.000574715"/>
      <joint name="joint_proximal_thumb" pos="0 0 0" axis="0 0 -1" range="-3.14 0"/>
      <geom type="mesh" rgba="0.792157 0.819608 0.933333 1" mesh="proximal_thumb"/>

      <body name="mideal_thumb" pos="0.057231 -0.0078705 0.05561" quat="0.621175 0.337847 -0.621177 0.337848">
        <inertial pos="0.00231731 -0.0205965 -0.020482" quat="0.820309 -0.0326504 0.0171454 0.570731" mass="3.53888" diaginertia="0.002494 0.00244324 0.00108519"/>
        <joint name="joint_mideal_thumb" pos="0 0 0" axis="0 0 -1" range="-1.0 0"/>
        <geom pos="0 0 0" quat="0.000796327 1 0 0" type="mesh" rgba="0.792157 0.819608 0.933333 1" mesh="mideal_thumb"/>
        
        <body name="distal_thumb" pos="0.05861 0 0">
          <inertial pos="-0.0518558 0.01816 0.0196176" quat="0.582258 -0.0179308 0.0327711 0.812146" mass="3.66037" diaginertia="0.00255017 0.00249207 0.0011303"/>
          <joint name="joint_distal_thumb" pos="0 0 0" axis="0 0 -1" range="-1.57 0"/>
          <geom quat="0.000796327 1 0 0" type="mesh" rgba="0.792157 0.819608 0.933333 1" mesh="distal_thumb"/>
        </body>
      </body>
    </body>


    <body name="mideal_finger first" pos="-0.0298251 0.04467 0.06311" quat="0.000563087 0.707105 -0.000563089 0.707108">
      <inertial pos="0.00231731 -0.0205965 -0.020482" quat="0.820309 -0.0326504 0.0171454 0.570731" mass="3.53888" diaginertia="0.002494 0.00244324 0.00108519"/>
      <joint name="joint_mideal_finger_first" pos="0 0 0" axis="0 0 -1" range="-1.0 0"/>
      <geom pos="0 0 0" quat="0.000796327 1 0 0" type="mesh" rgba="0.792157 0.819608 0.933333 1" mesh="mideal_finger first"/>
      
      <body name="distal_finger_first" pos="0.05861 0 0">
        <inertial pos="-0.0518558 0.01816 0.0196176" quat="0.582258 -0.0179308 0.0327711 0.812146" mass="3.66037" diaginertia="0.00255017 0.00249207 0.0011303"/>
        <joint name="joint_distal_finger_first" pos="0 0 0" axis="0 0 -1" range="-1.57 0"/>
        <geom quat="0.000796327 1 0 0" type="mesh" rgba="0.792157 0.819608 0.933333 1" mesh="distal_finger first"/>
      </body>
    </body>


    <body name="mideal_finger_second" pos="0.019975 0.04486 0.06311" quat="0.707107 0 -0.707107 0">
      <inertial pos="0.00231731 -0.0205965 -0.020482" quat="0.820309 -0.0326504 0.0171454 0.570731" mass="3.53888" diaginertia="0.002494 0.00244324 0.00108519"/>
      <joint name="joint_mideal_finger_second" pos="0 0 0" axis="0 0 1" range="-1.0 0"/>
      <geom type="mesh" rgba="0.792157 0.819608 0.933333 1" mesh="mideal_finger_second"/>
      
      <body name="distal_finger_second" pos="0.05861 0 0">
        <inertial pos="-0.0518558 0.01816 0.0196176" quat="0.582258 -0.0179308 0.0327711 0.812146" mass="3.66037" diaginertia="0.00255017 0.00249207 0.0011303"/>
        <joint name="joint_distal_finger_second" pos="0 0 0" axis="0 0 1" range="-1.57 0"/>
        <geom type="mesh" rgba="0.792157 0.819608 0.933333 1" mesh="distal_finger_second"/>
      </body>
    </body>
  </worldbody>

  <actuator>
    <position name="thumb_0" joint="joint_proximal_thumb" ctrlrange="-3.14 0"/>
    <position name="thumb_1" joint="joint_mideal_thumb" ctrlrange="-1.0 0"/>
    <position name="thumb_2" joint="joint_distal_thumb" ctrlrange="-1.57 0"/>
    <position name="f_finger_0" joint="joint_mideal_finger_first" ctrlrange="-1.0 0"/>
    <position name="f_finger_1" joint="joint_distal_finger_first" ctrlrange="-1.57 0"/>
    <position name="s_finger_0" joint="joint_mideal_finger_second" ctrlrange="-1.0 0"/>
    <position name="s_finger_1" joint="joint_distal_finger_second" ctrlrange="-1.57 0"/>
  </actuator>


</mujoco>
